<?xml version="1.0"?>
<robot name="tao_moi">
<link name="base_link">
<visual>
<geometry>
<box size="0.8 0.5 0.05"/>
</geometry>
<origin rpy="0 0 0" xyz="0 0 0.05"/>
<material name="yellow">
<color rgba="1 1 1 1"/>
</material>
</visual>
<collision>
<geometry>
<box size="0.8 0.5 0.05"/>
</geometry>
</collision>
<inertial>
<mass value="1.0"/>
<inertia ixx="0.015" iyy="0.0375" izz="0.0375"
ixy="0" ixz="0" iyz="0"/>
</inertial>
</link>

<link name="right_wheel">
<visual>
<geometry>
<cylinder length="0.05" radius="0.05"/>
</geometry>
<material name="black">
<color rgba="0 0 0 1"/>
</material>
</visual>
<inertial>
<mass value="0.1"/>
<inertia ixx="5.1458e-5" iyy="5.1458e-5" izz="6.125e-5"
ixy="0" ixz="0" iyz="0"/>
</inertial>
</link>

<link name="left_wheel">
<visual>
<geometry>
<cylinder length="0.05" radius="0.05"/>
</geometry>
<material name="black"/>
</visual>
<inertial>
<mass value="0.1"/>
<inertia ixx="5.1458e-5" iyy="5.1458e-5" izz="6.125e-5"
ixy="0" ixz="0" iyz="0"/>
</inertial>
</link>

<link name="back_wheel">
<visual>
<geometry>
<cylinder length="0.05" radius="0.05"/>
</geometry>
<material name="black"/>
</visual>
<inertial>
<mass value="0.1"/>
<inertia ixx="0.00083" iyy="0.00083" izz="0.000167"
ixy="0" ixz="0" iyz="0"/>
</inertial>
</link>

<link name="colum1">
<visual>
<geometry>
<cylinder length="0.5" radius="0.03"/>
</geometry>
<material name="yellow">
</material>
</visual>
</link>
<joint name="joint_colum1" type="fixed">
<parent link="base_link"/>
<child link="colum1"/>
<origin rpy="0 0 0" xyz="-0.35 0.20 0.3"/>
</joint>
<link name="colum2">
<visual>
<geometry>
<cylinder length="0.5" radius="0.03"/>
</geometry>
<material name="yellow">
</material>
</visual>
</link>
<joint name="joint_colum2" type="fixed">
<parent link="base_link"/>
<child link="colum2"/>
<origin rpy="0 0 0" xyz="0.35 0.20 0.3"/>
</joint>

<joint name="base_to_left_wheel" type="continuous">
 <axis xyz="0 0 1"/>
<parent link="base_link"/>
<child link="left_wheel"/>
<origin rpy="0 1.5 0" xyz="-0.4 -0.20 0"/>
</joint>

<joint name="base_to_right_wheel" type="continuous">
	<axis xyz="0 0 1"/>
<parent link="base_link"/>
<child link="right_wheel"/>
<origin rpy="0 1.5 0" xyz="0.4 -0.20 0"/>
</joint>

<joint name="base_to_back_wheel" type="continuous">
	<axis xyz="0 0 1"/>
<parent link="base_link"/>
<child link="back_wheel"/>
<origin rpy="0 1.5 0" xyz="0 0.20 0"/>
</joint>
<gazebo>
<plugin name="differential_drive_controller"
filename="libgazebo_ros_diff_drive.so">
<leftJoint>base_to_left_wheel</leftJoint>
<rightJoint>base_to_right_wheel</rightJoint>
<robotBaseFrame>base_link</robotBaseFrame>
<wheelSeparation>0.25</wheelSeparation>
<wheelDiameter>0.07</wheelDiameter>
<publishWheelJointState>true</publishWheelJointState>
</plugin>


<plugin name="joint_state_publisher"
filename="libgazebo_ros_joint_state_publisher.so">
<jointName>base_to_back_wheel, base_to_right_wheel</jointName>
</plugin>
</gazebo>


</robot>
